<robot name="pantilt">
	<link name="base" />
	<link name="pan" >
		<visual>
			<geometry>
				<box size="0.05 0.05 0.05" />
			</geometry>
			<material name="green" >
				<color rgba="0.4 0.4 0.4 1" />
			</material>
		</visual>
	</link>

	<link name="tilt">
		<visual>
			<geometry>
				<box size="0.05 0.05 0.05" />
			</geometry>
			<material name="white" >
				<color rgba="0.8 0.8 0 1" />
			</material>
		</visual>
	</link>

	<joint name="panservo" type="continuous">
		<parent link="base" />
		<child link="pan" />
		<origin xyz="0 0 0.03" rpy="0 0 0" />
		<axis xyz="0 0 1" />
	</joint>

	<joint name="tiltservo" type="continuous">
		<parent link="pan" />
		<child link="tilt" />
		<origin xyz="-0.03 0 0.06" rpy="0 0 0" />
		<axis xyz="1 0 0" />
	</joint>

</robot>

